<?xml version="1.0" ?>
<robot name="circular_waiter_robot" xmlns:xacro="http://www.ros.org/wiki/xacro">

<!-- Realsense Camera Primary and Secondary -->
<xacro:arg name="realsense_enabled"             default="$(optenv HUSKY_REALSENSE_ENABLED 1)" />
<xacro:arg name="realsense_topic"               default="$(optenv HUSKY_REALSENSE_TOPIC realsense)" />
<xacro:arg name="realsense_prefix"              default="$(optenv HUSKY_REALSENSE_PREFIX camera)" />
<xacro:arg name="realsense_parent"              default="$(optenv HUSKY_REALSENSE_PARENT base_link)" />
<xacro:arg name="realsense_xyz"                 default="$(optenv HUSKY_REALSENSE_XYZ .14 0 .565)" />
<xacro:arg name="realsense_rpy"                 default="$(optenv HUSKY_REALSENSE_RPY 0 0.3 0)" />

<xacro:arg name="realsense_secondary_enabled"   default="$(optenv HUSKY_REALSENSE_SECONDARY_ENABLED 0)" />
<xacro:arg name="realsense_secondary_topic"     default="$(optenv HUSKY_REALSENSE_SECONDARY_TOPIC realsense_secondary)" />
<xacro:arg name="realsense_secondary_prefix"    default="$(optenv HUSKY_REALSENSE_SECONDARY_PREFIX camera_secondary)" />
<xacro:arg name="realsense_secondary_parent"    default="$(optenv HUSKY_REALSENSE_SECONDARY_PARENT base_link)" />
<xacro:arg name="realsense_secondary_xyz"       default="$(optenv HUSKY_REALSENSE_SECONDARY_XYZ 0 0 0)" />
<xacro:arg name="realsense_secondary_rpy"       default="$(optenv HUSKY_REALSENSE_SECONDARY_RPY 0 0 0)" />



<xacro:include filename="$(find circular_waiter_robot_description)/urdf/materials.xacro" />
<xacro:include filename="$(find circular_waiter_robot_description)/urdf/circular_waiter_robot.trans" />
<xacro:include filename="$(find circular_waiter_robot_description)/urdf/circular_waiter_robot.gazebo" />
<xacro:include filename="$(find circular_waiter_robot_description)/urdf/intel_realsense.urdf.xacro"/>
<link name="base_link">
  <inertial>
    <origin xyz="-0.0053059584965141696 1.616160100893701e-08 0.18069105446173542" rpy="0 0 0"/>
    <mass value="7.585934889059097"/>
    <inertia ixx="0.190339" iyy="0.198897" izz="0.119981" ixy="0.0" iyz="0.0" ixz="-0.001508"/>
  </inertial>
  <visual>
    <origin xyz="0 0 0" rpy="0 0 0"/>
    <geometry>
      <mesh filename="package://circular_waiter_robot_description/meshes/base_link.stl" scale="0.001 0.001 0.001"/>
    </geometry>
    <material name="white"/>
  </visual>
  <collision>
    <origin xyz="0 0 0" rpy="0 0 0"/>
    <geometry>
      <mesh filename="package://circular_waiter_robot_description/meshes/base_link.stl" scale="0.001 0.001 0.001"/>
    </geometry>
  </collision>
</link>

<link name="right_wheel_1">
  <inertial>
    <origin xyz="2.7000355657130202e-17 0.01750048395086569 1.3877787807814457e-17" rpy="0 0 0"/>
    <mass value="0.6265325415633612"/>
    <inertia ixx="0.001024" iyy="0.001927" izz="0.001024" ixy="-0.0" iyz="-0.0" ixz="0.0"/>
  </inertial>
  <visual>
    <origin xyz="-0.0 0.101114 -0.08" rpy="0 0 0"/>
    <geometry>
      <mesh filename="package://circular_waiter_robot_description/meshes/right_wheel_1.stl" scale="0.001 0.001 0.001"/>
    </geometry>
    <material name="black"/>
  </visual>
  <collision>
    <origin xyz="-0.0 0.101114 -0.08" rpy="0 0 0"/>
    <geometry>
      <mesh filename="package://circular_waiter_robot_description/meshes/right_wheel_1.stl" scale="0.001 0.001 0.001"/>
    </geometry>
  </collision>
</link>

<link name="left_wheel_1">
  <inertial>
    <origin xyz="2.7000355657130202e-17 -0.01750048395086569 0.0" rpy="0 0 0"/>
    <mass value="0.6265325415633612"/>
    <inertia ixx="0.001024" iyy="0.001927" izz="0.001024" ixy="-0.0" iyz="0.0" ixz="0.0"/>
  </inertial>
  <visual>
    <origin xyz="-0.0 -0.101114 -0.08" rpy="0 0 0"/>
    <geometry>
      <mesh filename="package://circular_waiter_robot_description/meshes/left_wheel_1.stl" scale="0.001 0.001 0.001"/>
    </geometry>
    <material name="black"/>
  </visual>
  <collision>
    <origin xyz="-0.0 -0.101114 -0.08" rpy="0 0 0"/>
    <geometry>
      <mesh filename="package://circular_waiter_robot_description/meshes/left_wheel_1.stl" scale="0.001 0.001 0.001"/>
    </geometry>
  </collision>
</link>

<link name="camera_1">
  <inertial>
    <origin xyz="0.0013599752116220942 -6.109142609001834e-18 0.0" rpy="0 0 0"/>
    <mass value="0.0006451464615692233"/>
    <inertia ixx="0.0" iyy="0.0" izz="0.0" ixy="-0.0" iyz="0.0" ixz="-0.0"/>
  </inertial>
  <visual>
    <origin xyz="-0.1525 -0.0 -0.2" rpy="0 0 0"/>
    <geometry>
      <mesh filename="package://circular_waiter_robot_description/meshes/camera_1.stl" scale="0.001 0.001 0.001"/>
    </geometry>
    <material name="red"/>
  </visual>
  <collision>
    <origin xyz="-0.1525 -0.0 -0.2" rpy="0 0 0"/>
    <geometry>
      <mesh filename="package://circular_waiter_robot_description/meshes/camera_1.stl" scale="0.001 0.001 0.001"/>
    </geometry>
  </collision>
</link>

<link name="lidar_1">
  <inertial>
    <origin xyz="0.0 2.2189765115406322e-17 0.007499999999999979" rpy="0 0 0"/>
    <mass value="0.021338922545952342"/>
    <inertia ixx="3e-06" iyy="3e-06" izz="5e-06" ixy="0.0" iyz="0.0" ixz="0.0"/>
  </inertial>
  <visual>
    <origin xyz="-0.125 -0.0 -0.14" rpy="0 0 0"/>
    <geometry>
      <mesh filename="package://circular_waiter_robot_description/meshes/lidar_1.stl" scale="0.001 0.001 0.001"/>
    </geometry>
    <material name="black"/>
  </visual>
  <collision>
    <origin xyz="-0.125 -0.0 -0.14" rpy="0 0 0"/>
    <geometry>
      <mesh filename="package://circular_waiter_robot_description/meshes/lidar_1.stl" scale="0.001 0.001 0.001"/>
    </geometry>
  </collision>
</link>

<link name="front_caster_wheel_1">
  <inertial>
    <origin xyz="0.03999999999999973 -1.2022559695755379e-17 -0.012749999999999949" rpy="0 0 0"/>
    <mass value="0.04771293842639495"/>
    <inertia ixx="5e-06" iyy="5e-06" izz="5e-06" ixy="-0.0" iyz="0.0" ixz="0.0"/>
  </inertial>
  <visual>
    <origin xyz="-0.0825 -0.0 -0.03" rpy="0 0 0"/>
    <geometry>
      <mesh filename="package://circular_waiter_robot_description/meshes/front_caster_wheel_1.stl" scale="0.001 0.001 0.001"/>
    </geometry>
    <material name="silver"/>
  </visual>
  <collision>
    <origin xyz="-0.0825 -0.0 -0.03" rpy="0 0 0"/>
    <geometry>
      <mesh filename="package://circular_waiter_robot_description/meshes/front_caster_wheel_1.stl" scale="0.001 0.001 0.001"/>
    </geometry>
  </collision>
</link>

<link name="rear_caster_wheel_1">
  <inertial>
    <origin xyz="-0.03999999999999991 3.579423759522287e-18 -0.012749999999999945" rpy="0 0 0"/>
    <mass value="0.04771293842639496"/>
    <inertia ixx="5e-06" iyy="5e-06" izz="5e-06" ixy="-0.0" iyz="-0.0" ixz="-0.0"/>
  </inertial>
  <visual>
    <origin xyz="0.0825 -0.0 -0.03" rpy="0 0 0"/>
    <geometry>
      <mesh filename="package://circular_waiter_robot_description/meshes/rear_caster_wheel_1.stl" scale="0.001 0.001 0.001"/>
    </geometry>
    <material name="silver"/>
  </visual>
  <collision>
    <origin xyz="0.0825 -0.0 -0.03" rpy="0 0 0"/>
    <geometry>
      <mesh filename="package://circular_waiter_robot_description/meshes/rear_caster_wheel_1.stl" scale="0.001 0.001 0.001"/>
    </geometry>
  </collision>
</link>

<!-- Intel Realsense Primary and Secondary -->
<xacro:if value="$(arg realsense_enabled)">
  <link name="$(arg realsense_prefix)_realsense_mountpoint"/>
  <joint name="$(arg realsense_prefix)_realsense_mountpoint_joint" type="fixed">
    <origin xyz="$(arg realsense_xyz)" rpy="$(arg realsense_rpy)" />
    <parent link="$(arg realsense_parent)"/>
    <child link="$(arg realsense_prefix)_realsense_mountpoint" />
  </joint>
  <xacro:intel_realsense_mount prefix="$(arg realsense_prefix)" topic="$(arg realsense_topic)" parent_link="$(arg realsense_prefix)_realsense_mountpoint"/>
</xacro:if>

<xacro:if value="$(arg realsense_secondary_enabled)">
  <link name="$(arg realsense_secondary_prefix)_realsense_mountpoint"/>
  <joint name="$(arg realsense_secondary_prefix)_realsense_mountpoint_joint" type="fixed">
    <origin xyz="$(arg realsense_secondary_xyz)" rpy="$(arg realsense_secondary_rpy)" />
    <parent link="$(arg realsense_secondary_parent)"/>
    <child link="$(arg realsense_secondary_prefix)_realsense_mountpoint" />
  </joint>
  <xacro:intel_realsense_mount prefix="$(arg realsense_secondary_prefix)" topic="$(arg realsense_secondary_topic)" parent_link="$(arg realsense_secondary_prefix)_realsense_mountpoint"/>
</xacro:if>


<joint name="right_wheel_joint" type="continuous">
  <origin xyz="0.0 -0.101114 0.08" rpy="0 0 0"/>
  <parent link="base_link"/>
  <child link="right_wheel_1"/>
  <axis xyz="0.0 1.0 0.0"/>
</joint>

<joint name="left_wheel_joint" type="continuous">
  <origin xyz="0.0 0.101114 0.08" rpy="0 0 0"/>
  <parent link="base_link"/>
  <child link="left_wheel_1"/>
  <axis xyz="0.0 1.0 0.0"/>
</joint>

<joint name="camera" type="fixed">
  <origin xyz="0.1525 0.0 0.2" rpy="0 0 0"/>
  <parent link="base_link"/>
  <child link="camera_1"/>
</joint>

<joint name="lidar" type="fixed">
  <origin xyz="0.125 0.0 0.14" rpy="0 0 0"/>
  <parent link="base_link"/>
  <child link="lidar_1"/>
</joint>

<joint name="front_caster_wheel_joint" type="fixed">
  <origin xyz="0.0825 0.0 0.03" rpy="0 0 0"/>
  <parent link="base_link"/>
  <child link="front_caster_wheel_1"/>
</joint>

<joint name="rear_caster_wheel_joint" type="fixed">
  <origin xyz="-0.0825 0.0 0.03" rpy="0 0 0"/>
  <parent link="base_link"/>
  <child link="rear_caster_wheel_1"/>
</joint>

</robot>
